<!DOCTYPE html>
<html lang="en">
<head>
    <meta charset="UTF-8">
    <title>Title</title>
</head>
<body>
<script type="text/javascript">

    // TODO JS实现逻辑要求：以下两个延时函数。比如我想先延时1秒，在延迟2秒，再延时1秒，最后输出“完成”。

    const setDelay = (millisecond) => {
        return new Promise((resolve, reject) => {
            if (typeof millisecond != 'number') reject(new Error('参数必须是number类型'));
            setTimeout(() => {
                resolve(`我延迟了${millisecond}毫秒后输出的`)
            }, millisecond);
        });
    }
    const setDelaySecond = (seconds) => {
        return new Promise((resolve, reject) => {
            if (typeof seconds != 'number' || seconds > 10) reject(new Error('参数必须是number类型，并且小于等于10'));
            setTimeout(() => {
                resolve(`我延迟了${seconds}秒后输出的，注意单位是秒`)
            }, seconds * 1000);
        });
    }


    // 方法一：如果用then的写法，大概是这样（嵌套地狱写法出门右拐不送）：
    setDelay(1000)
        .then(result => {
            console.log(result);
            return setDelaySecond(2);
        })
        .then(result => {
            console.log(result);
            return setDelay(1000);
        })
        .then(result => {
            console.log(result);
            console.log('完成');
        })
        .catch(err => {
            console.log(err);
        })

    // 方法二：使用 async/await ，没有冗余的长长的链式代码，语义化也非常清楚，非常舒服
    const chainType = async () => {
        const result = await setDelay(1000);
        console.log(result);
        console.log(await setDelaySecond(2));
        console.log(await setDelay(1000));
        console.log('完成了');
    }


    // TODO async函数中捕获错误
    // 方法一：除了catch()方法，可以使用try...catch语句
    const tryCatch = async () => {
        try {
            const result = await setDelay(1000);
            console.log(result);
            console.log(await setDelaySecond(2));
            console.log(await setDelay(1000));
            console.log('完成了');
        } catch (e) {
            console.log(e); // 这里捕获错误
        }
    }

    // 方法二：如果不想因为一个的错误就整个process都crash掉，可以拆分开分别处理
    const splitting = async () => {
        const result = await setDelay(1000).catch(err => {
            console.log(err);
        });
        console.log(result);
        const result1 = await setDelaySecond(12).catch(err => {
            console.log(err);
        })
        console.log(result1);
        console.log(await setDelay(1000));
        console.log('完成了');
    }

    // 方法三：改进一下，封装一下提取错误的代码函数
    function to(promise) {
        return promise.then(data => {
            return [null, data];
        }).catch(err => [err]); // es6的返回写法
    }
    const encapsulation = async () => {
        // es6的写法，返回一个数组，第一个是错误信息，第二个是then的异步返回数据
        [err, result] = await to(setDelay(1000));
        // 如果err存在就是有错，不想继续执行就抛出错误
        if (err) throw new Error('出现错误，同时我不想执行了');
        console.log(result);
        [err, result1] = await to(setDelaySecond(12));
        // 还想执行就不要抛出错误
        if (err) console.log('出现错误，同时我想继续执行', err);
        console.log(result1);
        console.log(await setDelay(1000));
        console.log('完成了');
    }

</script>
</body>
</html>